<robot
  name="ezn64_model">
  <link
    name="ezn64_base_link">
    <inertial>
      <origin
        xyz="-0.0597472396167027 -0.00105462552475217 1.03388922491662E-05"
        rpy="0 0 0" />
      <mass
        value="0.292531716256714" />
      <inertia
        ixx="0.000127280528424294"
        ixy="1.70352243549314E-05"
        ixz="1.18923384991819E-07"
        iyy="0.000494637894497754"
        iyz="-4.08383573670305E-08"
        izz="0.000506767672669245" />
    </inertial>
    <visual>
      <origin
        xyz="0 0 0"
        rpy="0 0 0" />
      <geometry>
        <mesh
          filename="package://ezn64_model/meshes/ezn64_base_link.STL" />
      </geometry>
      <material
        name="">
        <color
          rgba="0.819607843137255 0.819607843137255 0.819607843137255 1" />
      </material>
    </visual>
    <collision>
      <origin
        xyz="0 0 0"
        rpy="0 0 0" />
      <geometry>
        <mesh
          filename="package://ezn64_model/meshes/ezn64_base_link.STL" />
      </geometry>
    </collision>
  </link>
  <link
    name="ezn64_finger_1">
    <inertial>
      <origin
        xyz="0.00709005979737385 -0.000260000509586692 -0.0102744701962787"
        rpy="0 0 0" />
      <mass
        value="0.00614599943010827" />
      <inertia
        ixx="5.87624825788296E-07"
        ixy="1.69661588831627E-14"
        ixz="-1.33685858752718E-08"
        iyy="5.87785468507411E-07"
        iyz="2.84080225024107E-15"
        izz="2.22775219868136E-07" />
    </inertial>
    <visual>
      <origin
        xyz="0 0 0"
        rpy="0 0 0" />
      <geometry>
        <mesh
          filename="package://ezn64_model/meshes/ezn64_finger_1.STL" />
      </geometry>
      <material
        name="">
        <color
          rgba="0.12156862745098 0.12156862745098 0.12156862745098 1" />
      </material>
    </visual>
    <collision>
      <origin
        xyz="0 0 0"
        rpy="0 0 0" />
      <geometry>
        <mesh
          filename="package://ezn64_model/meshes/ezn64_finger_1.STL" />
      </geometry>
    </collision>
  </link>
  <joint
    name="ezn64_joint_1"
    type="prismatic">
    <origin
      xyz="-0.01501 -0.0086667 0"
      rpy="-1.5708 0 0" />
    <parent
      link="ezn64_base_link" />
    <child
      link="ezn64_finger_1" />
    <axis
      xyz="0 0 -1" />
    <limit
      lower="0"
      upper="0.006"
      effort="0"
      velocity="0" />
  </joint>
  <link
    name="ezn64_finger_2">
    <inertial>
      <origin
        xyz="0.007090059798561 0.0102635175461303 0.000259999490413285"
        rpy="0 0 0" />
      <mass
        value="0.00614599942439724" />
      <inertia
        ixx="5.87624816021265E-07"
        ixy="1.33685954824186E-08"
        ixz="1.69655511564291E-14"
        iyy="2.2277521955471E-07"
        iyz="-3.52982932349008E-15"
        izz="5.87785458977903E-07" />
    </inertial>
    <visual>
      <origin
        xyz="0 0 0"
        rpy="0 0 0" />
      <geometry>
        <mesh
          filename="package://ezn64_model/meshes/ezn64_finger_2.STL" />
      </geometry>
      <material
        name="">
        <color
          rgba="0.12156862745098 0.12156862745098 0.12156862745098 1" />
      </material>
    </visual>
    <collision>
      <origin
        xyz="0 0 0"
        rpy="0 0 0" />
      <geometry>
        <mesh
          filename="package://ezn64_model/meshes/ezn64_finger_2.STL" />
      </geometry>
    </collision>
  </link>
  <joint
    name="ezn64_joint_2"
    type="prismatic">
    <origin
      xyz="-0.01501 0.0043333 0.0075056"
      rpy="1.0472 0 0" />
    <parent
      link="ezn64_base_link" />
    <child
      link="ezn64_finger_2" />
    <axis
      xyz="0 1 0" />
    <limit
      lower="0"
      upper="0.006"
      effort="0"
      velocity="0" />
  </joint>
  <link
    name="ezn64_finger_3">
    <inertial>
      <origin
        xyz="0.007090059798561 0.000260000509586661 0.0103109721293354"
        rpy="0 0 0" />
      <mass
        value="0.00614599942439724" />
      <inertia
        ixx="5.87624816021265E-07"
        ixy="-1.69655511001808E-14"
        ixz="1.33685954824186E-08"
        iyy="5.87785458977903E-07"
        iyz="3.52983010434858E-15"
        izz="2.22775219554709E-07" />
    </inertial>
    <visual>
      <origin
        xyz="0 0 0"
        rpy="0 0 0" />
      <geometry>
        <mesh
          filename="package://ezn64_model/meshes/ezn64_finger_3.STL" />
      </geometry>
      <material
        name="">
        <color
          rgba="0.12156862745098 0.12156862745098 0.12156862745098 1" />
      </material>
    </visual>
    <collision>
      <origin
        xyz="0 0 0"
        rpy="0 0 0" />
      <geometry>
        <mesh
          filename="package://ezn64_model/meshes/ezn64_finger_3.STL" />
      </geometry>
    </collision>
  </link>
  <joint
    name="ezn64_joint_3"
    type="prismatic">
    <origin
      xyz="-0.01501 0.0043333 -0.0075056"
      rpy="-2.618 0 0" />
    <parent
      link="ezn64_base_link" />
    <child
      link="ezn64_finger_3" />
    <axis
      xyz="0 0 1" />
    <limit
      lower="0"
      upper="0.006"
      effort="0"
      velocity="0" />
  </joint>
</robot>